Workbook

Sheet SYNTHESE
A1: Product Info Assistant : benchmark de 1 500 questions
A2: Campagne du 14/10 au 16/10/2026 · 300 conversations de 5 questions · un chat neuf par conversation. Tous les chiffres sont calculés par formules sur l’onglet DONNEES.
A3: Indicateur | B3: Valeur | C3: Commentaire
A4: Questions du benchmark | B4: =COUNTA(DONNEES!$A$2:$A$1501) -> 1500
A5: Réponses capturées | B5: =B4-COUNTIFS(DONNEES!$L$2:$L$1501,"Non capturé") -> 1485 | C5: Conversations non capturées : C048, C050, C052
A6: Questions à valeur connue notées | B6: =COUNTIFS(DONNEES!$H$2:$H$1501,"NOTABLE",DONNEES!$L$2:$L$1501,"Correct")+COUNTIFS(DONNEES!$H$2:$H$1501,"NOTABLE",DONNEES!$L$2:$L$1501,"Pas d’info à tort")+COUNTIFS(DONNEES!$H$2:$H$1501,"NOTABLE",DONNEES!$L$2:$L$1501,"Incorrect")+COUNTIFS(DONNEES!$H$2:$H$1501,"NOTABLE",DONNEES!$L$2:$L$1501,"Hors sujet") -> 1365 | C6: Dénominateur des taux ci-dessous (statut NOTABLE)
A7: Réponses justes | B7: =COUNTIFS(DONNEES!$H$2:$H$1501,"NOTABLE",DONNEES!$L$2:$L$1501,"Correct")/B6 -> 0.81098901 | C7: IC 95 % (bootstrap par conversation) : 78,0 % – 84,0 %
A8: « Aucune information » alors que la donnée existe | B8: =COUNTIFS(DONNEES!$H$2:$H$1501,"NOTABLE",DONNEES!$L$2:$L$1501,"Pas d’info à tort")/B6 -> 0.13626374 | C8: Défaut principal
A9: Valeurs fausses | B9: =COUNTIFS(DONNEES!$H$2:$H$1501,"NOTABLE",DONNEES!$L$2:$L$1501,"Incorrect")/B6 -> 0.035897436 | C9: Dont réponses sur un autre fonds : voir ERREURS
A10: Réponses hors sujet | B10: =COUNTIFS(DONNEES!$H$2:$H$1501,"NOTABLE",DONNEES!$L$2:$L$1501,"Hors sujet")/B6 -> 0.016849817 | C10: « Quel scope de recherche ? », question non reçue, réponse vide
A11: Justesse quand l’agent donne une valeur | B11: =COUNTIFS(DONNEES!$H$2:$H$1501,"NOTABLE",DONNEES!$L$2:$L$1501,"Correct")/(COUNTIFS(DONNEES!$H$2:$H$1501,"NOTABLE",DONNEES!$L$2:$L$1501,"Correct")+COUNTIFS(DONNEES!$H$2:$H$1501,"NOTABLE",DONNEES!$L$2:$L$1501,"Incorrect")) -> 0.95761246 | C11: IC 95 % : 94,2 % – 97,1 %
A12: Abstention correcte sur cellule vide | B12: =COUNTIFS(DONNEES!$L$2:$L$1501,"Abstention correcte")/(COUNTIFS(DONNEES!$L$2:$L$1501,"Abstention correcte")+COUNTIFS(DONNEES!$L$2:$L$1501,"Valeur sur cellule vide")) -> 0.96521739 | C12: Cellules vides dans la base : l’agent n’invente pas
A13: Latence moyenne (s) | B13: =AVERAGE(DONNEES!$O$2:$O$1501) -> 18.452727 | C13: Médiane : 12.4 s · premier message : 34 s de médiane
A14: Chats ouverts | B14: =COUNTA(TENTATIVES!$A$2:$A$422) -> 421
A15: Chats interrompus | B15: =COUNTIFS(TENTATIVES!$D$2:$D$422,"FAILED") -> 121 | C15: 117 sans réponse au premier message en 6 minutes
A16: Justes, septembre (mêmes questions) | B16: =COUNTIFS(DONNEES!$H$2:$H$1501,"NOTABLE",DONNEES!$S$2:$S$1501,"Oui",DONNEES!$R$2:$R$1501,"Correct")/(COUNTIFS(DONNEES!$H$2:$H$1501,"NOTABLE",DONNEES!$S$2:$S$1501,"Oui",DONNEES!$R$2:$R$1501,"Correct")+COUNTIFS(DONNEES!$H$2:$H$1501,"NOTABLE",DONNEES!$S$2:$S$1501,"Oui",DONNEES!$R$2:$R$1501,"Pas d’info à tort")+COUNTIFS(DONNEES!$H$2:$H$1501,"NOTABLE",DONNEES!$S$2:$S$1501,"Oui",DONNEES!$R$2:$R$1501,"Incorrect")+COUNTIFS(DONNEES!$H$2:$H$1501,"NOTABLE",DONNEES!$S$2:$S$1501,"Oui",DONNEES!$R$2:$R$1501,"Hors sujet")) -> 0.86011342 | C16: Campagne du 29/09 (100 questions par chat), renotée avec les mêmes règles
A17: Justes, octobre (mêmes questions) | B17: =COUNTIFS(DONNEES!$H$2:$H$1501,"NOTABLE",DONNEES!$S$2:$S$1501,"Oui",DONNEES!$L$2:$L$1501,"Correct")/(COUNTIFS(DONNEES!$H$2:$H$1501,"NOTABLE",DONNEES!$L$2:$L$1501,"Correct",DONNEES!$S$2:$S$1501,"Oui")+COUNTIFS(DONNEES!$H$2:$H$1501,"NOTABLE",DONNEES!$L$2:$L$1501,"Pas d’info à tort",DONNEES!$S$2:$S$1501,"Oui")+COUNTIFS(DONNEES!$H$2:$H$1501,"NOTABLE",DONNEES!$L$2:$L$1501,"Incorrect",DONNEES!$S$2:$S$1501,"Oui")+COUNTIFS(DONNEES!$H$2:$H$1501,"NOTABLE",DONNEES!$L$2:$L$1501,"Hors sujet",DONNEES!$S$2:$S$1501,"Oui")) -> 0.8317757 | C17: Un chat neuf par conversation
A18: Questions qui changent de verdict | B18: =1-(COMPARAISON_SEPT!B20+COMPARAISON_SEPT!C21+COMPARAISON_SEPT!D22+COMPARAISON_SEPT!E23)/SUM(COMPARAISON_SEPT!B20:E23) -> 0.16888046 | C18: Entre septembre et octobre, questions notées dans les deux campagnes
A20: Répartition des verdicts
A21: Verdict | B21: Réponses
A22: Correct | B22: =COUNTIFS(DONNEES!$L$2:$L$1501,"Correct") -> 1107
A23: Pas d’info à tort | B23: =COUNTIFS(DONNEES!$L$2:$L$1501,"Pas d’info à tort") -> 186
A24: Incorrect | B24: =COUNTIFS(DONNEES!$L$2:$L$1501,"Incorrect") -> 49
A25: Hors sujet | B25: =COUNTIFS(DONNEES!$L$2:$L$1501,"Hors sujet") -> 26
A26: Abstention correcte | B26: =COUNTIFS(DONNEES!$L$2:$L$1501,"Abstention correcte") -> 111
A27: Valeur sur cellule vide | B27: =COUNTIFS(DONNEES!$L$2:$L$1501,"Valeur sur cellule vide") -> 4
A28: Échec technique | B28: =COUNTIFS(DONNEES!$L$2:$L$1501,"Échec technique") -> 2
A29: Non capturé | B29: =COUNTIFS(DONNEES!$L$2:$L$1501,"Non capturé") -> 15

Sheet LISEZ-MOI
A1: Lisez-moi
A3: Onglets
A4: SYNTHESE | B4: Chiffres clés et répartition des verdicts.
A5: DONNEES | B5: Une ligne par question : question, valeur attendue, réponse, verdict, motif, latence, verdict de septembre. Filtrable.
A6: PAR_FAMILLE / TOUR / CHAMP / FONDS / GROUPE | B6: Résultats par dimension, avec graphique pour familles et tours.
A7: CROISEMENT | B7: Famille × tour (% correct) et famille × verdict (nombres).
A8: COMPARAISON_SEPT | B8: Mêmes questions en septembre et en octobre, et passage de verdict de l’une à l’autre.
A9: ERREURS | B9: Valeurs fausses et réponses hors sujet, classées par type.
A10: COLLECTE / TENTATIVES | B10: Chats ouverts et interrompus par heure, latence par tour, détail des tentatives.
A12: Verdicts
A13: Correct | B13: La valeur de la base est restituée (équivalences FR / EN acceptées).
A14: Pas d’info à tort | B14: L’agent dit ne pas avoir la donnée alors qu’elle est renseignée.
A15: Incorrect | B15: Autre valeur, champ voisin, ou réponse portant sur un autre fonds.
A16: Hors sujet | B16: L’agent ne traite pas la question : demande de « scope de recherche », question non reçue, réponse vide, définition générique.
A17: Abstention correcte | B17: Cellule vide dans la base, l’agent ne donne pas de valeur.
A18: Valeur sur cellule vide | B18: Cellule vide dans la base, l’agent affirme une valeur.
A19: Échec technique | B19: Message d’erreur de la plateforme.
A20: Non capturé | B20: Question non capturée (conversation interrompue 3 fois).
A22: Taux | B22: Calculés sur les questions à valeur connue (statut NOTABLE) notées Correct, « Aucune info », Valeur fausse ou Hors sujet.
A23: Source du verdict | B23: « Règles » : notation automatique. « Revue des écarts » : 68 cas ambigus ou réponses sur un autre fonds.
A24: Relecture | B24: Pour corriger un verdict, modifier la colonne « Verdict » de DONNEES : tous les onglets se recalculent.
A25: Familles de champs | B25: Gérants et dates de gestion : portfolio manager, portfolio backup, start date; Intervenants : depositary, custodian, centralizing, transfer agent, administrator, auditor, commissaire, investment manager, delegation, sponsoring, management company, promoter; Identifiants : isin, lei, amf code, code; Juridique et réglementaire : legal form, regulation, umbrella, domicil, priips, eet fund, sub-regulation, fund of funds, feeder, status, statut, internal classification, amf classification; Risque : risk, sri, volatility, liquidity, counterparty, credit risk; ESG / EET : esg, sfdr, eet, pai, taxonomy, article 29, label, finansol, thematic, sustainab, \bsi\b; Frais et coûts : fee, cost, tarification, rétrocession, retrocession, high water, performance; Expertise et gamme : expertise, asset class, fund range, region, benchmark, investment universe; Textes longs : objective, allocation, investor profile, strategy; Dates et VL : date, nav, closing, period, maturity

Sheet DONNEES
A1: ID question | B1: Conversation | C1: Tour | D1: Groupe | E1: Famille de champs | F1: Produit | G1: Champ | H1: Statut GT | I1: Question posée | J1: Valeur attendue (base) | K1: Réponse de l’agent | L1: Verdict | M1: Motif | N1: Source du verdict | O1: Latence (s) | P1: Tentative | Q1: Capture (heure de Paris) | R1: Verdict septembre | S1: Comparable septembre | T1: Évolution
A2: Q0001 | B2: C001 | C2: 1 | D2: PRIORITAIRE | E2: Gérants et dates de gestion | F2: R-co Target 2028 IG | G2: Portfolio Manager | H2: NOTABLE | I2: Je prépare une fiche sur R-co Target 2028 IG : peux-tu me donner le nom du gérant principal ? | J2: PETIT Emmanuel | K2: Résultat Information trouvée Le gérant principal du fonds « R-co Target 2028 IG » (version en statut Production) est : Emmanuel PETIT. Détails complémentaires Aucune information complémentaire pertinente pour cette demande. | L2: Correct | M2: mots (ordre libre) | N2: Règles | O2: 60.48 | P2: 1 | Q2: 46309.784 | R2: Correct | S2: Oui | T2: =IF(S2="Oui",IF(R2=L2,"Identique","Changé"),"") -> Identique
A3: Q0002 | B3: C001 | C3: 2 | D3: PRIORITAIRE | E3: Gérants et dates de gestion | F3: R-co Target 2028 IG | G3: Portfolio Manager backup 1 | H3: NOTABLE | I3: Au passage, qui figure comme premier gérant de renfort ? | J3: LOMNE Philippe | K3: Résultat Information trouvée Le premier gérant de renfort du fonds « R-co Target 2028 IG » (statut Production) est Philippe LOMNE. Détails complémentaires Aucune information complémentaire pertinente pour cette demande. | L3: Correct | M3: mots (ordre libre) | N3: Règles | O3: 12.74 | P3: 1 | Q3: 46309.784 | R3: Correct | S3: Oui | T3: =IF(S3="Oui",IF(R3=L3,"Identique","Changé"),"") -> Identique
A4: Q0003 | B4: C001 | C4: 3 | D4: PRIORITAIRE | E4: Juridique et réglementaire | F4: R-co Strategic Metals and Mining | G4: Legal Form | H4: NOTABLE | I4: Je passe à R-co Strategic Metals and Mining : est-ce que tu as sa forme juridique ? | J4: SICAV | K4: Résultat Information trouvée La forme juridique du fonds « R-co Strategic Metals and Mining » est : SICAV. Détails complémentaires Aucune information complémentaire pertinente pour cette demande. | L4: Correct | M4: texte | N4: Règles | O4: 8.9 | P4: 1 | Q4: 46309.784 | R4: Correct | S4: Oui | T4: =IF(S4="Oui",IF(R4=L4,"Identique","Changé"),"") -> Identique
A5: Q0004 | B5: C001 | C5: 4 | D5: PRIORITAIRE | E5: ESG / EET | F5: R-co Strategic Metals and Mining | G5: ESG - SFDR Article | H5: NOTABLE | I5: Sans changer de fonds, il relève de quel article SFDR ? | J5: Article 8 | K5: Résultat Information trouvée Le fonds « R-co Strategic Metals and Mining » relève de l’Article 8 du règlement SFDR. Détails complémentaires Aucune information complémentaire pertinente pour cette demande. | L5: Correct | M5: texte | N5: Règles | O5: 11.01 | P5: 1 | Q5: 46309.784 | R5: Correct | S5: Oui | T5: =IF(S5="Oui",IF(R5=L5,"Identique","Changé"),"") -> Identique
A6: Q0005 | B6: C001 | C6: 5 | D6: PRIORITAIRE | E6: Intervenants | F6: R-co Target 2028 IG | G6: Depositary | H6: NOTABLE | I6: Je reviens à R-co Target 2028 IG : quel établissement assure le dépôt ? Réponds uniquement sur ce point. | J6: Rothschild & Co Martin Maurel | K6: Rothschild & Co Martin Maurel. | L6: Correct | M6: texte | N6: Règles | O6: 12.01 | P6: 1 | Q6: 46309.785 | R6: Correct | S6: Oui | T6: =IF(S6="Oui",IF(R6=L6,"Identique","Changé"),"") -> Identique
A7: Q0006 | B7: C002 | C7: 1 | D7: CONTRASTE | E7: Juridique et réglementaire | F7: Argosphère | G7: Legal Form | H7: NOTABLE | I7: Pour Argosphère, quelle forme juridique est indiquée ? | J7: Unit Trust | K7: Résultat Information trouvée Pour le fonds « Argosphère », la forme juridique indiquée est : FCP (Fonds Commun de Placement). Détails complémentaires Le fonds Argosphère est présent en statut Production dans le référentiel. | L7: Correct | M7: texte | N7: Règles | O7: 49.27 | P7: 3 | Q7: 46309.795 | R7: Correct | S7: Oui | T7: =IF(S7="Oui",IF(R7=L7,"Identique","Changé"),"") -> Identique
A8: Q0007 | B8: C002 | C8: 2 | D8: CONTRASTE | E8: Juridique et réglementaire | F8: Argosphère | G8: Applicable UCI Regulation | H8: NOTABLE | I8: Pour compléter la fiche, quelle réglementation OPC lui est applicable ? | J8: UCITS | K8: Résultat Information trouvée Pour le fonds « Argosphère », la réglementation OPC applicable est : OPCVM. | L8: Correct | M8: texte | N8: Règles | O8: 7.6 | P8: 3 | Q8: 46309.795 | R8: Correct | S8: Oui | T8: =IF(S8="Oui",IF(R8=L8,"Identique","Changé"),"") -> Identique
A9: Q0008 | B9: C002 | C9: 3 | D9: CONTRASTE | E9: Juridique et réglementaire | F9: Argosphère | G9: Domiciliation | H9: NOTABLE | I9: Sans changer de fonds, où est-il domicilié ? | J9: France | K9: Résultat Information trouvée Le fonds « Argosphère » est domicilié en France. Détails complémentaires Sa forme juridique est FCP et sa réglementation applicable est OPCVM. | L9: Correct | M9: texte | N9: Règles | O9: 7.69 | P9: 3 | Q9: 46309.795 | R9: Correct | S9: Oui | T9: =IF(S9="Oui",IF(R9=L9,"Identique","Changé"),"") -> Identique
A10: Q0009 | B10: C002 | C10: 4 | D10: CONTRASTE | E10: Gérants et dates de gestion | F10: Argosphère | G10: Portfolio Manager backup 2 | H10: EXPLORATOIRE | I10: Et pour ce même produit, qui est indiqué comme deuxième gérant secondaire ? | J10: nan | K10: Résultat Information trouvée Aucun deuxième gérant secondaire n'est renseigné pour le fonds « Argosphère ». Détails complémentaires Le champ correspondant au deuxième gérant secondaire ne contient pas de valeur pour ce produit dans le référentiel. | L10: Abstention correcte | M10: cellule vide, l'agent n'invente pas | N10: Règles | O10: 10.12 | P10: 3 | Q10: 46309.795 | R10: Abstention correcte | S10: Oui | T10: =IF(S10="Oui",IF(R10=L10,"Identique","Changé"),"") -> Identique
A11: Q0010 | B11: C002 | C11: 5 | D11: CONTRASTE | E11: Risque | F11: Argosphère | G11: Official Risk Scale | H11: NOTABLE | I11: Autre point sur ce fonds : quel niveau est indiqué sur l’échelle officielle de risque ? | J11: 3 | K11: Résultat Information trouvée Aucun niveau n'est renseigné pour l’échelle officielle de risque du fonds « Argosphère ». Détails complémentaires Le champ correspondant à l’échelle officielle de risque est vide dans le référentiel pour ce fonds. | L11: Pas d’info à tort | M11: l'agent dit ne pas avoir la donnée | N11: Règles | O11: 11.13 | P11: 3 | Q11: 46309.796 | S11: Non | T11: =IF(S11="Oui",IF(R11=L11,"Identique","Changé"),"")
A12: Q0011 | B12: C003 | C12: 1 | D12: PRIORITAIRE | E12: Juridique et réglementaire | F12: R-co Valor 4Change Global Equity | G12: Legal Form | H12: NOTABLE | I12: Je regarde R-co Valor 4Change Global Equity. Est-ce que tu as sa forme juridique ? | J12: SICAV | K12: Résultat Information trouvée La forme juridique du fonds « R-co Valor 4Change Global Equity » est : SICAV. Détails complémentaires Le fonds a été trouvé en statut Production et sa forme juridique enregistrée est SICAV. | L12: Correct | M12: texte | N12: Règles | O12: 27.52 | P12: 1 | Q12: 46309.796 | S12: Non | T12: =IF(S12="Oui",IF(R12=L12,"Identique","Changé"),"")
A13: Q0012 | B13: C003 | C13: 2 | D13: PRIORITAIRE | E13: Expertise et gamme | F13: R-co Valor 4Change Global Equity | G13: Region | H13: NOTABLE | I13: Sans changer de fonds, quelle zone d’investissement est indiquée ? | J13: World | K13: Résultat Information trouvée Aucune information disponible pour cette demande. Détails complémentaires Le fonds « R-co Valor 4Change Global Equity » est bien présent en Production, mais aucune zone d’investissement n’est renseignée dans les données disponibles pour ce fonds. | L13: Pas d’info à tort | M13: l'agent dit ne pas avoir la donnée | N13: Règles | O13: 17.8 | P13: 1 | Q13: 46309.796 | S13: Non | T13: =IF(S13="Oui",IF(R13=L13,"Identique","Changé"),"")
A14: Q0013 | B14: C003 | C14: 3 | D14: PRIORITAIRE | E14: Risque | F14: R-co Valor 4Change Global Equity | G14: Official Risk Scale | H14: NOTABLE | I14: Et pour ce même produit, quelle est sa note de risque officielle ? | J14: 4 | K14: Résultat Information trouvée Aucune information disponible pour cette demande. Détails complémentaires Pour le fonds « R-co Valor 4Change Global Equity », aucune note de risque officielle n’est renseignée dans les données disponibles du référentiel Product Info. | L14: Pas d’info à tort | M14: l'agent dit ne pas avoir la donnée | N14: Règles | O14: 8.36 | P14: 1 | Q14: 46309.797 | S14: Non | T14: =IF(S14="Oui",IF(R14=L14,"Identique","Changé"),"")
A15: Q0014 | B15: C003 | C15: 4 | D15: PRIORITAIRE | E15: Gérants et dates de gestion | F15: R-co Valor 4Change Global Equity | G15: Portfolio Manager backup 3 | H15: EXPLORATOIRE | I15: Autre point sur ce fonds : y a-t-il un troisième gérant secondaire renseigné ? | J15: nan | K15: Résultat Information trouvée Non, aucun troisième gérant secondaire n’est renseigné pour le fonds « R-co Valor 4Change Global Equity ». Détails complémentaires Le champ correspondant au troisième gérant secondaire est vide dans les données disponibles du référentiel Product Info. | L15: Abstention correcte | M15: cellule vide, l'agent n'invente pas | N15: Règles | O15: 11.49 | P15: 1 | Q15: 46309.797 | S15: Non | T15: =IF(S15="Oui",IF(R15=L15,"Identique","Changé"),"")
A16: Q0015 | B16: C003 | C16: 5 | D16: PRIORITAIRE | E16: Dates et VL | F16: R-co Valor 4Change Global Equity | G16: Recommended Investment Period | H16: NOTABLE | I16: Au passage, sur combien de temps est-il conseillé de le conserver ? | J16: 5 years | K16: Résultat Information trouvée Pour le fonds « R-co Valor 4Change Global Equity », la durée de détention recommandée est de : 5 ans. Détails complémentaires Cette durée correspond à l’horizon d’investissement recommandé enregistré pour ce fonds dans le référentiel Product Info. | L16: Correct | M16: texte | N16: Règles | O16: 9.02 | P16: 1 | Q16: 46309.797 | S16: Non | T16: =IF(S16="Oui",IF(R16=L16,"Identique","Changé"),"")
A17: Q0016 | B17: C004 | C17: 1 | D17: CONTRASTE | E17: Intervenants | F17: Synergizz Compartiment n°1 | G17: Investment Manager | H17: NOTABLE | I17: Je prépare une fiche sur Synergizz Compartiment n°1 : quelle société de gestion est indiquée ? | J17: Rothschild & Co Asset Management | K17: Résultat Pour le fonds/compartiment « Synergizz Compartiment n°1 », la société de gestion indiquée est : « Rothschild & Co Asset Management ». Détails complémentaires Cette information est rattachée au compartiment « Synergizz Compartiment n°1 » dans le référentiel Product Info. | L17: Correct | M17: texte | N17: Règles | O17: 46.85 | P17: 1 | Q17: 46309.798 | S17: Non | T17: =IF(S17="Oui",IF(R17=L17,"Identique","Changé"),"")
A18: Q0017 | B18: C004 | C18: 2 | D18: CONTRASTE | E18: Intervenants | F18: Synergizz Compartiment n°1 | G18: Depositary | H18: NOTABLE | I18: Et pour ce même produit, quel établissement assure le dépôt ? | J18: Caceis Bank | K18: Résultat Pour « Synergizz Compartiment n°1 », l’établissement dépositaire indiqué est : « Caceis Bank ». Détails complémentaires Caceis Bank est l’établissement renseigné comme dépositaire pour ce produit. | L18: Correct | M18: texte | N18: Règles | O18: 11.23 | P18: 1 | Q18: 46309.798 | S18: Non | T18: =IF(S18="Oui",IF(R18=L18,"Identique","Changé"),"")
A19: Q0018 | B19: C004 | C19: 3 | D19: CONTRASTE | E19: Risque | F19: Synergizz Compartiment n°1 | G19: Official Risk Scale | H19: NOTABLE | I19: Autre point sur ce fonds : quel niveau est indiqué sur l’échelle officielle de risque ? | J19: 3 | K19: Résultat Pour « Synergizz Compartiment n°1 », aucune valeur n’est renseignée dans le champ « échelle officielle de risque ». Détails complémentaires Une valeur de risque de niveau « 3 » est toutefois renseignée dans les informations de risque du produit et apparaît de manière cohérente dans les données disponibles du fonds. | L19: Pas d’info à tort | M19: l'agent dit ne pas avoir la donnée | N19: Règles | O19: 10.94 | P19: 1 | Q19: 46309.798 | S19: Non | T19: =IF(S19="Oui",IF(R19=L19,"Identique","Changé"),"")
A20: Q0019 | B20: C004 | C20: 4 | D20: CONTRASTE | E20: Intervenants | F20: Synergizz Compartiment n°1 | G20: Fund Administrator | H20: NOTABLE | I20: Au passage, quel administrateur est renseigné ? | J20: Caceis Fund Administration | K20: Résultat Pour « Synergizz Compartiment n°1 », l’administrateur (valorisateur) renseigné est : « Caceis Fund Administration ». Détails complémentaires Caceis Fund Administration est l’établissement enregistré comme administrateur du fonds dans le référentiel Product Info. | L20: Correct | M20: texte | N20: Règles | O20: 12.64 | P20: 1 | Q20: 46309.798 | S20: Non | T20: =IF(S20="Oui",IF(R20=L20,"Identique","Changé"),"")
A21: Q0020 | B21: C004 | C21: 5 | D21: CONTRASTE | E21: Intervenants | F21: Synergizz Compartiment n°1 | G21: Commissaire Aux Comptes | H21: NOTABLE | I21: Pour compléter la fiche, qui est le commissaire aux comptes ? | J21: PricewaterhouseCoopers Audit | K21: Résultat Pour « Synergizz Compartiment n°1 », le commissaire aux comptes renseigné est : « PricewaterhouseCoopers Audit ». Détails complémentaires PricewaterhouseCoopers Audit est l’entité enregistrée comme commissaire aux comptes du fonds dans le référentiel Product Info. | L21: Correct | M21: texte | N21: Règles | O21: 10.69 | P21: 1 | Q21: 46309.799 | S21: Non | T21: =IF(S21="Oui",IF(R21=L21,"Identique","Changé"),"")
A22: Q0021 | B22: C005 | C22: 1 | D22: PRIORITAIRE | E22: Gérants et dates de gestion | F22: R-co Thematic Silver Plus | G22: Portfolio Manager | H22: NOTABLE | I22: Pour R-co Thematic Silver Plus, quel gérant est indiqué en premier ? | J22: BOURDONCLE Nathalie | K22: Résultat Pour le fonds R-co Thematic Silver Plus, le gérant indiqué en premier (gérant principal) est : Nathalie BOURDONCLE Détails complémentaires Aucun autre détail demandé. Le fonds consulté est en statut Production. | L22: Correct | M22: mots (ordre libre) | N22: Règles | O22: 23.99 | P22: 1 | Q22: 46309.799 | S22: Non | T22: =IF(S22="Oui",IF(R22=L22,"Identique","Changé"),"")
... A101: Q0100 | B101: C020 | C101: 5 | D101: CONTRASTE | E101: Expertise et gamme | F101: RMM Court Terme | G101: Benchmark | H101: NOTABLE | I101: Sans changer de fonds, un indicateur de référence est-il signalé dans le champ Benchmark ? | J101: No | K101: Résultat Information trouvée Non, pour le fonds RMM Court Terme, le champ indiquant la présence d’un indicateur de référence (Benchmark) est renseigné à : Non. Détails complémentaires Aucun benchmark n’est signalé pour ce fonds dans les données disponibles. Le champ « Benchmark » est positionné sur « Non ». | L101: Correct | M101: texte | N101: Règles | O101: 12.1 | P101: 6 | Q101: 46310.426 | S101: Non | T101: =IF(S101="Oui",IF(R101=L101,"Identique","Changé"),"")
A102: Q0101 | B102: C021 | C102: 1 | D102: PRIORITAIRE | E102: Expertise et gamme | F102: R-co Conviction Club | G102: Management Expertise Level 1 | H102: NOTABLE | I102: Je regarde R-co Conviction Club. Tu as sa famille d’expertise de gestion ? | J102: DIVERSIFIED | K102: Résultat Information trouvée Pour le fonds R-co Conviction Club, la famille d’expertise de gestion est : Niveau 0 : DIRECT INVESTMENT Niveau 1 : DIVERSIFIED Niveau 2 : Flexible Niveau 3 (classe d’actif) : Diversified Détails complémentaires Le chemin d’expertise de gestion enregistré est : Diversified < Flexible < DIVERSIFIED < DIRECT INVESTMENT. | L102: Correct | M102: texte | N102: Règles | O102: 36.95 | P102: 3 | Q102: 46309.962 | R102: Correct | S102: Oui | T102: =IF(S102="Oui",IF(R102=L102,"Identique","Changé"),"") -> Identique
A103: Q0102 | B103: C021 | C103: 2 | D103: PRIORITAIRE | E103: Gérants et dates de gestion | F103: R-co Conviction Club | G103: Portfolio Manager backup 1 | H103: NOTABLE | I103: Au passage, quel est le premier gérant secondaire ? | J103: BOY Julien | K103: Résultat Information trouvée Le premier gérant secondaire de R-co Conviction Club est : Julien BOY Détails complémentaires Aucune autre information n’a été demandée sur les autres rôles de gestion. | L103: Correct | M103: mots (ordre libre) | N103: Règles | O103: 9.81 | P103: 3 | Q103: 46309.963 | R103: Correct | S103: Oui | T103: =IF(S103="Oui",IF(R103=L103,"Identique","Changé"),"") -> Identique
A104: Q0103 | B104: C021 | C104: 3 | D104: PRIORITAIRE | E104: ESG / EET | F104: R-co Target 2029 IG | G104: Does it consider PAI? (EET 20100) | H104: NOTABLE | I104: Je passe à R-co Target 2029 IG : le champ PAI est-il à oui ou à non ? | J104: Yes | K104: Résultat Information trouvée Pour le fonds R-co Target 2029 IG, le champ PAI est à : Oui Détails complémentaires Les indicateurs EET associés consultés pour ce fonds sont renseignés à « Oui ». Le fonds est également classé Article 8. | L104: Correct | M104: texte | N104: Règles | O104: 22.75 | P104: 3 | Q104: 46309.963 | R104: Correct | S104: Oui | T104: =IF(S104="Oui",IF(R104=L104,"Identique","Changé"),"") -> Identique
A105: Q0104 | B105: C021 | C105: 4 | D105: PRIORITAIRE | E105: Gérants et dates de gestion | F105: R-co Target 2029 IG | G105: Portfolio Manager | H105: NOTABLE | I105: Sans changer de fonds, qui gère principalement ce fonds ? | J105: PETIT Emmanuel | K105: Résultat Information trouvée Le gérant principal du fonds R-co Target 2029 IG est : Emmanuel PETIT Détails complémentaires Aucune autre information de gestion n’a été demandée pour ce fonds. | L105: Correct | M105: mots (ordre libre) | N105: Règles | O105: 9.42 | P105: 3 | Q105: 46309.963 | R105: Correct | S105: Oui | T105: =IF(S105="Oui",IF(R105=L105,"Identique","Changé"),"") -> Identique
A106: Q0105 | B106: C021 | C106: 5 | D106: PRIORITAIRE | E106: ESG / EET | F106: R-co Conviction Club | G106: ESG - SFDR Article | H106: NOTABLE | I106: Je reviens à R-co Conviction Club : quelle classification SFDR est renseignée ? | J106: Article 8 | K106: Résultat Information trouvée La classification SFDR renseignée pour le fonds R-co Conviction Club est : Article 8 Détails complémentaires Aucune autre classification SFDR n’est renseignée pour ce fonds. | L106: Correct | M106: texte | N106: Règles | O106: 7.59 | P106: 3 | Q106: 46309.963 | R106: Correct | S106: Oui | T106: =IF(S106="Oui",IF(R106=L106,"Identique","Changé"),"") -> Identique
A107: Q0106 | B107: C022 | C107: 1 | D107: CONTRASTE | E107: Intervenants | F107: R-co Core Equity Euro | G107: Investment Manager | H107: NOTABLE | I107: Je prépare une fiche sur R-co Core Equity Euro : quelle société de gestion est indiquée ? | J107: Rothschild & Co Asset Management | K107: Résultat Information trouvée Pour le fonds R-co Core Equity Euro, la société de gestion indiquée est : Rothschild & Co Asset Management Détails complémentaires Le fonds est présent en statut Production dans le référentiel. | L107: Correct | M107: texte | N107: Règles | O107: 43.92 | P107: 4 | Q107: 46310.426 | R107: Correct | S107: Oui | T107: =IF(S107="Oui",IF(R107=L107,"Identique","Changé"),"") -> Identique
A108: Q0107 | B108: C022 | C108: 2 | D108: CONTRASTE | E108: Intervenants | F108: R-co Core Equity Euro | G108: Depositary | H108: NOTABLE | I108: Pour compléter la fiche, quel établissement assure le dépôt ? | J108: Rothschild & Co Martin Maurel | K108: Résultat Information trouvée Pour le fonds R-co Core Equity Euro, l’établissement dépositaire indiqué est : Rothschild & Co Martin Maurel Détails complémentaires Cet établissement est renseigné comme dépositaire du fonds dans le référentiel de production. | L108: Correct | M108: texte | N108: Règles | O108: 16.03 | P108: 4 | Q108: 46310.427 | R108: Correct | S108: Oui | T108: =IF(S108="Oui",IF(R108=L108,"Identique","Changé"),"") -> Identique
A109: Q0108 | B109: C022 | C109: 3 | D109: CONTRASTE | E109: Expertise et gamme | F109: R-co Core Equity Euro | G109: Benchmark | H109: NOTABLE | I109: Sans changer de fonds, un indicateur de référence est-il signalé dans le champ Benchmark ? | J109: No | K109: Résultat Information trouvée Pour le fonds R-co Core Equity Euro, aucun indicateur de référence n’est signalé dans le champ Benchmark : Benchmark : Non Détails complémentaires Aucun indice de référence n’est renseigné comme benchmark pour ce fonds dans les données de production. | L109: Correct | M109: texte | N109: Règles | O109: 12.16 | P109: 4 | Q109: 46310.427 | R109: Correct | S109: Oui | T109: =IF(S109="Oui",IF(R109=L109,"Identique","Changé"),"") -> Identique
A110: Q0109 | B110: C022 | C110: 4 | D110: CONTRASTE | E110: Dates et VL | F110: R-co Core Equity Euro | G110: First NAV Date | H110: EXPLORATOIRE | I110: Et pour ce même produit, tu as sa date de première valeur liquidative ? Si tu ne trouves pas, dis-le clairement. | J110: nan | K110: Résultat Information trouvée Je ne trouve pas de date de première valeur liquidative renseignée pour le fonds R-co Core Equity Euro. Détails complémentaires Le champ correspondant à la première valeur liquidative est présent dans le référentiel, mais aucune valeur n’est enregistrée pour ce produit en production. | L110: Abstention correcte | M110: cellule vide, l'agent n'invente pas | N110: Règles | O110: 14.12 | P110: 4 | Q110: 46310.427 | R110: Abstention correcte | S110: Oui | T110: =IF(S110="Oui",IF(R110=L110,"Identique","Changé"),"") -> Identique
A111: Q0110 | B111: C022 | C111: 5 | D111: CONTRASTE | E111: Juridique et réglementaire | F111: R-co Core Equity Euro | G111: Legal Form | H111: NOTABLE | I111: Autre point sur ce fonds : quelle forme juridique est indiquée ? Réponds uniquement sur ce point. | J111: Unit Trust | K111: FCP (Fonds Commun de Placement)। | L111: Correct | M111: texte | N111: Règles | O111: 9.1 | P111: 4 | Q111: 46310.427 | R111: Correct | S111: Oui | T111: =IF(S111="Oui",IF(R111=L111,"Identique","Changé"),"") -> Identique
A112: Q0111 | B112: C023 | C112: 1 | D112: PRIORITAIRE | E112: Expertise et gamme | F112: R-co Valor Balanced | G112: Asset Class | H112: NOTABLE | I112: Pour R-co Valor Balanced, quelle est sa classe d’actifs ? | J112: Diversified | K112: Résultat Information trouvée Pour le fonds R-co Valor Balanced (statut Production), la classe d’actifs est : Niveau 3 (Classe d’actifs) : Diversified Chemin d’expertise complet : Diversified < Flexible < DIVERSIFIED < DIRECT INVESTMENT Détails complémentaires Selon le référentiel Product Info, la « classe d’actifs » correspond au niveau 3 du Management d’expertise. Pour ce fonds, elle est renseignée à la valeur Diversified. | L112: Correct | M112: texte | N112: Règles | O112: 40.49 | P112: 2 | Q112: 46309.982 | R112: Correct | S112: Oui | T112: =IF(S112="Oui",IF(R112=L112,"Identique","Changé"),"") -> Identique
A113: Q0112 | B113: C023 | C113: 2 | D113: PRIORITAIRE | E113: Expertise et gamme | F113: R-co Valor Balanced | G113: Benchmark | H113: NOTABLE | I113: Sans changer de fonds, un indicateur de référence est-il signalé dans le champ Benchmark ? | J113: No | K113: Pouvez-vous fournir la requête SQL SELECT que vous souhaitez exécuter ? | L113: Hors sujet | M113: l'agent ne traite pas la question (précision demandée, question non reçue ou réponse vide) | N113: Règles | O113: 5.16 | P113: 2 | Q113: 46309.982 | R113: Correct | S113: Oui | T113: =IF(S113="Oui",IF(R113=L113,"Identique","Changé"),"") -> Changé
... A146: Q0145 | B146: C029 | C146: 5 | D146: PRIORITAIRE | E146: Juridique et réglementaire | F146: R-co Conviction High Yield Euro | G146: Applicable UCI Regulation | H146: NOTABLE | I146: Pour compléter la fiche, quelle réglementation OPC lui est applicable ? Réponds uniquement sur ce point. | J146: UCITS | K146: OPCVM. | L146: Correct | M146: texte | N146: Règles | O146: 26 | P146: 4 | Q146: 46310.441 | R146: Correct | S146: Oui | T146: =IF(S146="Oui",IF(R146=L146,"Identique","Changé"),"") -> Identique
A147: Q0146 | B147: C030 | C147: 1 | D147: CONTRASTE | E147: Juridique et réglementaire | F147: Alfred Investment | G147: Domiciliation | H147: NOTABLE | I147: Je regarde Alfred Investment. Où est-il domicilié ? | J147: France | L147: Hors sujet | M147: l'agent ne traite pas la question (précision demandée, question non reçue ou réponse vide) | N147: Règles | O147: 18.06 | P147: 4 | Q147: 46310.441 | R147: Correct | S147: Oui | T147: =IF(S147="Oui",IF(R147=L147,"Identique","Changé"),"") -> Changé
A148: Q0147 | B148: C030 | C148: 2 | D148: CONTRASTE | E148: Juridique et réglementaire | F148: Alfred Investment | G148: Legal Form | H148: NOTABLE | I148: Autre point sur ce fonds : est-ce que tu as sa forme juridique ? | J148: SICAV | K148: Je ne peux pas répondre à la forme juridique de ce fonds avec les informations disponibles dans notre échange. Le fonds « Alfred Investment » n’a pas été retrouvé dans les données auxquelles j’ai accès. Sans pouvoir identifier précisément le fonds, je ne peux pas récupérer sa forme juridique. Si vous disposez du nom exact du fonds, d’un code ISIN ou du nom d’une part associée, je pourrai refaire la recherche. | L148: Pas d’info à tort | M148: l'agent dit ne pas avoir la donnée | N148: Règles | O148: 17.92 | P148: 4 | Q148: 46310.442 | R148: Correct | S148: Oui | T148: =IF(S148="Oui",IF(R148=L148,"Identique","Changé"),"") -> Changé
A149: Q0148 | B149: C030 | C149: 3 | D149: CONTRASTE | E149: Intervenants | F149: Alfred Investment | G149: Depositary | H149: NOTABLE | I149: Au passage, qui est le dépositaire ? | J149: Caceis Bank | K149: Je ne peux pas identifier le dépositaire du fonds concerné. Dans notre échange, le fonds « Alfred Investment » n’a pas été retrouvé dans les données disponibles, et je n’ai donc pas pu accéder à sa fiche produit. Sans identification certaine du fonds, il n’est pas possible de récupérer son dépositaire. Si vous disposez du nom exact du fonds, d’un code ISIN ou du nom d’une part associée, je pourrai vérifier le dépositaire. | L149: Pas d’info à tort | M149: l'agent dit ne pas avoir la donnée | N149: Règles | O149: 23.69 | P149: 4 | Q149: 46310.442 | R149: Correct | S149: Oui | T149: =IF(S149="Oui",IF(R149=L149,"Identique","Changé"),"") -> Changé
A150: Q0149 | B150: C030 | C150: 4 | D150: CONTRASTE | E150: Dates et VL | F150: Alfred Investment | G150: Recommended Investment Period | H150: NOTABLE | I150: Pour compléter la fiche, sur combien de temps est-il conseillé de le conserver ? | J150: 5 years | K150: Résultat Information trouvée Pour le fonds Alfred Investment, la durée de détention recommandée est de 5 ans. Détails complémentaires Statut : Production Durée de détention recommandée : 5 ans | L150: Correct | M150: texte | N150: Règles | O150: 17.42 | P150: 4 | Q150: 46310.442 | R150: Correct | S150: Oui | T150: =IF(S150="Oui",IF(R150=L150,"Identique","Changé"),"") -> Identique
...

Sheet PAR_FAMILLE
A1: Résultats par famille de champs
A2: Familles triées de la plus faible à la plus forte (% correct). Regroupement des champs : voir LISEZ-MOI.
A4: Famille de champs | B4: Notées | C4: Correct | D4: « Aucune info » à tort | E4: Valeur fausse | F4: Hors sujet | G4: % correct | H4: % aucune info | I4: % faux | J4: % hors sujet | K4: Latence moy. (s)
A5: Risque | B5: =COUNTIFS(DONNEES!$H$2:$H$1501,"NOTABLE",DONNEES!$L$2:$L$1501,"Correct",DONNEES!$E$2:$E$1501,$A5)+COUNTIFS(DONNEES!$H$2:$H$1501,"NOTABLE",DONNEES!$L$2:$L$1501,"Pas d’info à tort",DONNEES!$E$2:$E$1501,$A5)+COUNTIFS(DONNEES!$H$2:$H$1501,"NOTABLE",DONNEES!$L$2:$L$1501,"Incorrect",DONNEES!$E$2:$E$1501,$A5)+COUNTIFS(DONNEES!$H$2:$H$1501,"NOTABLE",DONNEES!$L$2:$L$1501,"Hors sujet",DONNEES!$E$2:$E$1501,$A5) -> 110 | C5: =COUNTIFS(DONNEES!$H$2:$H$1501,"NOTABLE",DONNEES!$L$2:$L$1501,"Correct",DONNEES!$E$2:$E$1501,$A5) -> 53 | D5: =COUNTIFS(DONNEES!$H$2:$H$1501,"NOTABLE",DONNEES!$L$2:$L$1501,"Pas d’info à tort",DONNEES!$E$2:$E$1501,$A5) -> 56 | E5: =COUNTIFS(DONNEES!$H$2:$H$1501,"NOTABLE",DONNEES!$L$2:$L$1501,"Incorrect",DONNEES!$E$2:$E$1501,$A5) -> 0 | F5: =COUNTIFS(DONNEES!$H$2:$H$1501,"NOTABLE",DONNEES!$L$2:$L$1501,"Hors sujet",DONNEES!$E$2:$E$1501,$A5) -> 1 | G5: =IF($B5=0,"",C5/$B5) -> 0.48181818 | H5: =IF($B5=0,"",D5/$B5) -> 0.50909091 | I5: =IF($B5=0,"",E5/$B5) -> 0 | J5: =IF($B5=0,"",F5/$B5) -> 0.0090909091 | K5: =IFERROR(AVERAGEIFS(DONNEES!$O$2:$O$1501,DONNEES!$E$2:$E$1501,$A5),"") -> 20.267273
A6: ESG / EET | B6: =COUNTIFS(DONNEES!$H$2:$H$1501,"NOTABLE",DONNEES!$L$2:$L$1501,"Correct",DONNEES!$E$2:$E$1501,$A6)+COUNTIFS(DONNEES!$H$2:$H$1501,"NOTABLE",DONNEES!$L$2:$L$1501,"Pas d’info à tort",DONNEES!$E$2:$E$1501,$A6)+COUNTIFS(DONNEES!$H$2:$H$1501,"NOTABLE",DONNEES!$L$2:$L$1501,"Incorrect",DONNEES!$E$2:$E$1501,$A6)+COUNTIFS(DONNEES!$H$2:$H$1501,"NOTABLE",DONNEES!$L$2:$L$1501,"Hors sujet",DONNEES!$E$2:$E$1501,$A6) -> 262 | C6: =COUNTIFS(DONNEES!$H$2:$H$1501,"NOTABLE",DONNEES!$L$2:$L$1501,"Correct",DONNEES!$E$2:$E$1501,$A6) -> 203 | D6: =COUNTIFS(DONNEES!$H$2:$H$1501,"NOTABLE",DONNEES!$L$2:$L$1501,"Pas d’info à tort",DONNEES!$E$2:$E$1501,$A6) -> 38 | E6: =COUNTIFS(DONNEES!$H$2:$H$1501,"NOTABLE",DONNEES!$L$2:$L$1501,"Incorrect",DONNEES!$E$2:$E$1501,$A6) -> 17 | F6: =COUNTIFS(DONNEES!$H$2:$H$1501,"NOTABLE",DONNEES!$L$2:$L$1501,"Hors sujet",DONNEES!$E$2:$E$1501,$A6) -> 4 | G6: =IF($B6=0,"",C6/$B6) -> 0.77480916 | H6: =IF($B6=0,"",D6/$B6) -> 0.14503817 | I6: =IF($B6=0,"",E6/$B6) -> 0.064885496 | J6: =IF($B6=0,"",F6/$B6) -> 0.015267176 | K6: =IFERROR(AVERAGEIFS(DONNEES!$O$2:$O$1501,DONNEES!$E$2:$E$1501,$A6),"") -> 18.137491
A7: Expertise et gamme | B7: =COUNTIFS(DONNEES!$H$2:$H$1501,"NOTABLE",DONNEES!$L$2:$L$1501,"Correct",DONNEES!$E$2:$E$1501,$A7)+COUNTIFS(DONNEES!$H$2:$H$1501,"NOTABLE",DONNEES!$L$2:$L$1501,"Pas d’info à tort",DONNEES!$E$2:$E$1501,$A7)+COUNTIFS(DONNEES!$H$2:$H$1501,"NOTABLE",DONNEES!$L$2:$L$1501,"Incorrect",DONNEES!$E$2:$E$1501,$A7)+COUNTIFS(DONNEES!$H$2:$H$1501,"NOTABLE",DONNEES!$L$2:$L$1501,"Hors sujet",DONNEES!$E$2:$E$1501,$A7) -> 135 | C7: =COUNTIFS(DONNEES!$H$2:$H$1501,"NOTABLE",DONNEES!$L$2:$L$1501,"Correct",DONNEES!$E$2:$E$1501,$A7) -> 107 | D7: =COUNTIFS(DONNEES!$H$2:$H$1501,"NOTABLE",DONNEES!$L$2:$L$1501,"Pas d’info à tort",DONNEES!$E$2:$E$1501,$A7) -> 22 | E7: =COUNTIFS(DONNEES!$H$2:$H$1501,"NOTABLE",DONNEES!$L$2:$L$1501,"Incorrect",DONNEES!$E$2:$E$1501,$A7) -> 4 | F7: =COUNTIFS(DONNEES!$H$2:$H$1501,"NOTABLE",DONNEES!$L$2:$L$1501,"Hors sujet",DONNEES!$E$2:$E$1501,$A7) -> 2 | G7: =IF($B7=0,"",C7/$B7) -> 0.79259259 | H7: =IF($B7=0,"",D7/$B7) -> 0.16296296 | I7: =IF($B7=0,"",E7/$B7) -> 0.02962963 | J7: =IF($B7=0,"",F7/$B7) -> 0.014814815 | K7: =IFERROR(AVERAGEIFS(DONNEES!$O$2:$O$1501,DONNEES!$E$2:$E$1501,$A7),"") -> 19.500815
A8: Frais et coûts | B8: =COUNTIFS(DONNEES!$H$2:$H$1501,"NOTABLE",DONNEES!$L$2:$L$1501,"Correct",DONNEES!$E$2:$E$1501,$A8)+COUNTIFS(DONNEES!$H$2:$H$1501,"NOTABLE",DONNEES!$L$2:$L$1501,"Pas d’info à tort",DONNEES!$E$2:$E$1501,$A8)+COUNTIFS(DONNEES!$H$2:$H$1501,"NOTABLE",DONNEES!$L$2:$L$1501,"Incorrect",DONNEES!$E$2:$E$1501,$A8)+COUNTIFS(DONNEES!$H$2:$H$1501,"NOTABLE",DONNEES!$L$2:$L$1501,"Hors sujet",DONNEES!$E$2:$E$1501,$A8) -> 192 | C8: =COUNTIFS(DONNEES!$H$2:$H$1501,"NOTABLE",DONNEES!$L$2:$L$1501,"Correct",DONNEES!$E$2:$E$1501,$A8) -> 159 | D8: =COUNTIFS(DONNEES!$H$2:$H$1501,"NOTABLE",DONNEES!$L$2:$L$1501,"Pas d’info à tort",DONNEES!$E$2:$E$1501,$A8) -> 16 | E8: =COUNTIFS(DONNEES!$H$2:$H$1501,"NOTABLE",DONNEES!$L$2:$L$1501,"Incorrect",DONNEES!$E$2:$E$1501,$A8) -> 14 | F8: =COUNTIFS(DONNEES!$H$2:$H$1501,"NOTABLE",DONNEES!$L$2:$L$1501,"Hors sujet",DONNEES!$E$2:$E$1501,$A8) -> 3 | G8: =IF($B8=0,"",C8/$B8) -> 0.828125 | H8: =IF($B8=0,"",D8/$B8) -> 0.083333333 | I8: =IF($B8=0,"",E8/$B8) -> 0.072916667 | J8: =IF($B8=0,"",F8/$B8) -> 0.015625 | K8: =IFERROR(AVERAGEIFS(DONNEES!$O$2:$O$1501,DONNEES!$E$2:$E$1501,$A8),"") -> 17.708
A9: Textes longs | B9: =COUNTIFS(DONNEES!$H$2:$H$1501,"NOTABLE",DONNEES!$L$2:$L$1501,"Correct",DONNEES!$E$2:$E$1501,$A9)+COUNTIFS(DONNEES!$H$2:$H$1501,"NOTABLE",DONNEES!$L$2:$L$1501,"Pas d’info à tort",DONNEES!$E$2:$E$1501,$A9)+COUNTIFS(DONNEES!$H$2:$H$1501,"NOTABLE",DONNEES!$L$2:$L$1501,"Incorrect",DONNEES!$E$2:$E$1501,$A9)+COUNTIFS(DONNEES!$H$2:$H$1501,"NOTABLE",DONNEES!$L$2:$L$1501,"Hors sujet",DONNEES!$E$2:$E$1501,$A9) -> 79 | C9: =COUNTIFS(DONNEES!$H$2:$H$1501,"NOTABLE",DONNEES!$L$2:$L$1501,"Correct",DONNEES!$E$2:$E$1501,$A9) -> 66 | D9: =COUNTIFS(DONNEES!$H$2:$H$1501,"NOTABLE",DONNEES!$L$2:$L$1501,"Pas d’info à tort",DONNEES!$E$2:$E$1501,$A9) -> 11 | E9: =COUNTIFS(DONNEES!$H$2:$H$1501,"NOTABLE",DONNEES!$L$2:$L$1501,"Incorrect",DONNEES!$E$2:$E$1501,$A9) -> 1 | F9: =COUNTIFS(DONNEES!$H$2:$H$1501,"NOTABLE",DONNEES!$L$2:$L$1501,"Hors sujet",DONNEES!$E$2:$E$1501,$A9) -> 1 | G9: =IF($B9=0,"",C9/$B9) -> 0.83544304 | H9: =IF($B9=0,"",D9/$B9) -> 0.13924051 | I9: =IF($B9=0,"",E9/$B9) -> 0.012658228 | J9: =IF($B9=0,"",F9/$B9) -> 0.012658228 | K9: =IFERROR(AVERAGEIFS(DONNEES!$O$2:$O$1501,DONNEES!$E$2:$E$1501,$A9),"") -> 17.494
A10: Juridique et réglementaire | B10: =COUNTIFS(DONNEES!$H$2:$H$1501,"NOTABLE",DONNEES!$L$2:$L$1501,"Correct",DONNEES!$E$2:$E$1501,$A10)+COUNTIFS(DONNEES!$H$2:$H$1501,"NOTABLE",DONNEES!$L$2:$L$1501,"Pas d’info à tort",DONNEES!$E$2:$E$1501,$A10)+COUNTIFS(DONNEES!$H$2:$H$1501,"NOTABLE",DONNEES!$L$2:$L$1501,"Incorrect",DONNEES!$E$2:$E$1501,$A10)+COUNTIFS(DONNEES!$H$2:$H$1501,"NOTABLE",DONNEES!$L$2:$L$1501,"Hors sujet",DONNEES!$E$2:$E$1501,$A10) -> 172 | C10: =COUNTIFS(DONNEES!$H$2:$H$1501,"NOTABLE",DONNEES!$L$2:$L$1501,"Correct",DONNEES!$E$2:$E$1501,$A10) -> 149 | D10: =COUNTIFS(DONNEES!$H$2:$H$1501,"NOTABLE",DONNEES!$L$2:$L$1501,"Pas d’info à tort",DONNEES!$E$2:$E$1501,$A10) -> 13 | E10: =COUNTIFS(DONNEES!$H$2:$H$1501,"NOTABLE",DONNEES!$L$2:$L$1501,"Incorrect",DONNEES!$E$2:$E$1501,$A10) -> 6 | F10: =COUNTIFS(DONNEES!$H$2:$H$1501,"NOTABLE",DONNEES!$L$2:$L$1501,"Hors sujet",DONNEES!$E$2:$E$1501,$A10) -> 4 | G10: =IF($B10=0,"",C10/$B10) -> 0.86627907 | H10: =IF($B10=0,"",D10/$B10) -> 0.075581395 | I10: =IF($B10=0,"",E10/$B10) -> 0.034883721 | J10: =IF($B10=0,"",F10/$B10) -> 0.023255814 | K10: =IFERROR(AVERAGEIFS(DONNEES!$O$2:$O$1501,DONNEES!$E$2:$E$1501,$A10),"") -> 16.439017
A11: Autres | B11: =COUNTIFS(DONNEES!$H$2:$H$1501,"NOTABLE",DONNEES!$L$2:$L$1501,"Correct",DONNEES!$E$2:$E$1501,$A11)+COUNTIFS(DONNEES!$H$2:$H$1501,"NOTABLE",DONNEES!$L$2:$L$1501,"Pas d’info à tort",DONNEES!$E$2:$E$1501,$A11)+COUNTIFS(DONNEES!$H$2:$H$1501,"NOTABLE",DONNEES!$L$2:$L$1501,"Incorrect",DONNEES!$E$2:$E$1501,$A11)+COUNTIFS(DONNEES!$H$2:$H$1501,"NOTABLE",DONNEES!$L$2:$L$1501,"Hors sujet",DONNEES!$E$2:$E$1501,$A11) -> 68 | C11: =COUNTIFS(DONNEES!$H$2:$H$1501,"NOTABLE",DONNEES!$L$2:$L$1501,"Correct",DONNEES!$E$2:$E$1501,$A11) -> 59 | D11: =COUNTIFS(DONNEES!$H$2:$H$1501,"NOTABLE",DONNEES!$L$2:$L$1501,"Pas d’info à tort",DONNEES!$E$2:$E$1501,$A11) -> 7 | E11: =COUNTIFS(DONNEES!$H$2:$H$1501,"NOTABLE",DONNEES!$L$2:$L$1501,"Incorrect",DONNEES!$E$2:$E$1501,$A11) -> 1 | F11: =COUNTIFS(DONNEES!$H$2:$H$1501,"NOTABLE",DONNEES!$L$2:$L$1501,"Hors sujet",DONNEES!$E$2:$E$1501,$A11) -> 1 | G11: =IF($B11=0,"",C11/$B11) -> 0.86764706 | H11: =IF($B11=0,"",D11/$B11) -> 0.10294118 | I11: =IF($B11=0,"",E11/$B11) -> 0.014705882 | J11: =IF($B11=0,"",F11/$B11) -> 0.014705882 | K11: =IFERROR(AVERAGEIFS(DONNEES!$O$2:$O$1501,DONNEES!$E$2:$E$1501,$A11),"") -> 16.235
A12: Intervenants | B12: =COUNTIFS(DONNEES!$H$2:$H$1501,"NOTABLE",DONNEES!$L$2:$L$1501,"Correct",DONNEES!$E$2:$E$1501,$A12)+COUNTIFS(DONNEES!$H$2:$H$1501,"NOTABLE",DONNEES!$L$2:$L$1501,"Pas d’info à tort",DONNEES!$E$2:$E$1501,$A12)+COUNTIFS(DONNEES!$H$2:$H$1501,"NOTABLE",DONNEES!$L$2:$L$1501,"Incorrect",DONNEES!$E$2:$E$1501,$A12)+COUNTIFS(DONNEES!$H$2:$H$1501,"NOTABLE",DONNEES!$L$2:$L$1501,"Hors sujet",DONNEES!$E$2:$E$1501,$A12) -> 186 | C12: =COUNTIFS(DONNEES!$H$2:$H$1501,"NOTABLE",DONNEES!$L$2:$L$1501,"Correct",DONNEES!$E$2:$E$1501,$A12) -> 164 | D12: =COUNTIFS(DONNEES!$H$2:$H$1501,"NOTABLE",DONNEES!$L$2:$L$1501,"Pas d’info à tort",DONNEES!$E$2:$E$1501,$A12) -> 15 | E12: =COUNTIFS(DONNEES!$H$2:$H$1501,"NOTABLE",DONNEES!$L$2:$L$1501,"Incorrect",DONNEES!$E$2:$E$1501,$A12) -> 3 | F12: =COUNTIFS(DONNEES!$H$2:$H$1501,"NOTABLE",DONNEES!$L$2:$L$1501,"Hors sujet",DONNEES!$E$2:$E$1501,$A12) -> 4 | G12: =IF($B12=0,"",C12/$B12) -> 0.88172043 | H12: =IF($B12=0,"",D12/$B12) -> 0.080645161 | I12: =IF($B12=0,"",E12/$B12) -> 0.016129032 | J12: =IF($B12=0,"",F12/$B12) -> 0.021505376 | K12: =IFERROR(AVERAGEIFS(DONNEES!$O$2:$O$1501,DONNEES!$E$2:$E$1501,$A12),"") -> 20.812941
A13: Dates et VL | B13: =COUNTIFS(DONNEES!$H$2:$H$1501,"NOTABLE",DONNEES!$L$2:$L$1501,"Correct",DONNEES!$E$2:$E$1501,$A13)+COUNTIFS(DONNEES!$H$2:$H$1501,"NOTABLE",DONNEES!$L$2:$L$1501,"Pas d’info à tort",DONNEES!$E$2:$E$1501,$A13)+COUNTIFS(DONNEES!$H$2:$H$1501,"NOTABLE",DONNEES!$L$2:$L$1501,"Incorrect",DONNEES!$E$2:$E$1501,$A13)+COUNTIFS(DONNEES!$H$2:$H$1501,"NOTABLE",DONNEES!$L$2:$L$1501,"Hors sujet",DONNEES!$E$2:$E$1501,$A13) -> 52 | C13: =COUNTIFS(DONNEES!$H$2:$H$1501,"NOTABLE",DONNEES!$L$2:$L$1501,"Correct",DONNEES!$E$2:$E$1501,$A13) -> 46 | D13: =COUNTIFS(DONNEES!$H$2:$H$1501,"NOTABLE",DONNEES!$L$2:$L$1501,"Pas d’info à tort",DONNEES!$E$2:$E$1501,$A13) -> 3 | E13: =COUNTIFS(DONNEES!$H$2:$H$1501,"NOTABLE",DONNEES!$L$2:$L$1501,"Incorrect",DONNEES!$E$2:$E$1501,$A13) -> 1 | F13: =COUNTIFS(DONNEES!$H$2:$H$1501,"NOTABLE",DONNEES!$L$2:$L$1501,"Hors sujet",DONNEES!$E$2:$E$1501,$A13) -> 2 | G13: =IF($B13=0,"",C13/$B13) -> 0.88461538 | H13: =IF($B13=0,"",D13/$B13) -> 0.057692308 | I13: =IF($B13=0,"",E13/$B13) -> 0.019230769 | J13: =IF($B13=0,"",F13/$B13) -> 0.038461538 | K13: =IFERROR(AVERAGEIFS(DONNEES!$O$2:$O$1501,DONNEES!$E$2:$E$1501,$A13),"") -> 15.66038
A14: Identifiants | B14: =COUNTIFS(DONNEES!$H$2:$H$1501,"NOTABLE",DONNEES!$L$2:$L$1501,"Correct",DONNEES!$E$2:$E$1501,$A14)+COUNTIFS(DONNEES!$H$2:$H$1501,"NOTABLE",DONNEES!$L$2:$L$1501,"Pas d’info à tort",DONNEES!$E$2:$E$1501,$A14)+COUNTIFS(DONNEES!$H$2:$H$1501,"NOTABLE",DONNEES!$L$2:$L$1501,"Incorrect",DONNEES!$E$2:$E$1501,$A14)+COUNTIFS(DONNEES!$H$2:$H$1501,"NOTABLE",DONNEES!$L$2:$L$1501,"Hors sujet",DONNEES!$E$2:$E$1501,$A14) -> 21 | C14: =COUNTIFS(DONNEES!$H$2:$H$1501,"NOTABLE",DONNEES!$L$2:$L$1501,"Correct",DONNEES!$E$2:$E$1501,$A14) -> 19 | D14: =COUNTIFS(DONNEES!$H$2:$H$1501,"NOTABLE",DONNEES!$L$2:$L$1501,"Pas d’info à tort",DONNEES!$E$2:$E$1501,$A14) -> 1 | E14: =COUNTIFS(DONNEES!$H$2:$H$1501,"NOTABLE",DONNEES!$L$2:$L$1501,"Incorrect",DONNEES!$E$2:$E$1501,$A14) -> 1 | F14: =COUNTIFS(DONNEES!$H$2:$H$1501,"NOTABLE",DONNEES!$L$2:$L$1501,"Hors sujet",DONNEES!$E$2:$E$1501,$A14) -> 0 | G14: =IF($B14=0,"",C14/$B14) -> 0.9047619 | H14: =IF($B14=0,"",D14/$B14) -> 0.047619048 | I14: =IF($B14=0,"",E14/$B14) -> 0.047619048 | J14: =IF($B14=0,"",F14/$B14) -> 0 | K14: =IFERROR(AVERAGEIFS(DONNEES!$O$2:$O$1501,DONNEES!$E$2:$E$1501,$A14),"") -> 14.6244
A15: Gérants et dates de gestion | B15: =COUNTIFS(DONNEES!$H$2:$H$1501,"NOTABLE",DONNEES!$L$2:$L$1501,"Correct",DONNEES!$E$2:$E$1501,$A15)+COUNTIFS(DONNEES!$H$2:$H$1501,"NOTABLE",DONNEES!$L$2:$L$1501,"Pas d’info à tort",DONNEES!$E$2:$E$1501,$A15)+COUNTIFS(DONNEES!$H$2:$H$1501,"NOTABLE",DONNEES!$L$2:$L$1501,"Incorrect",DONNEES!$E$2:$E$1501,$A15)+COUNTIFS(DONNEES!$H$2:$H$1501,"NOTABLE",DONNEES!$L$2:$L$1501,"Hors sujet",DONNEES!$E$2:$E$1501,$A15) -> 88 | C15: =COUNTIFS(DONNEES!$H$2:$H$1501,"NOTABLE",DONNEES!$L$2:$L$1501,"Correct",DONNEES!$E$2:$E$1501,$A15) -> 82 | D15: =COUNTIFS(DONNEES!$H$2:$H$1501,"NOTABLE",DONNEES!$L$2:$L$1501,"Pas d’info à tort",DONNEES!$E$2:$E$1501,$A15) -> 4 | E15: =COUNTIFS(DONNEES!$H$2:$H$1501,"NOTABLE",DONNEES!$L$2:$L$1501,"Incorrect",DONNEES!$E$2:$E$1501,$A15) -> 1 | F15: =COUNTIFS(DONNEES!$H$2:$H$1501,"NOTABLE",DONNEES!$L$2:$L$1501,"Hors sujet",DONNEES!$E$2:$E$1501,$A15) -> 1 | G15: =IF($B15=0,"",C15/$B15) -> 0.93181818 | H15: =IF($B15=0,"",D15/$B15) -> 0.045454545 | I15: =IF($B15=0,"",E15/$B15) -> 0.011363636 | J15: =IF($B15=0,"",F15/$B15) -> 0.011363636 | K15: =IFERROR(AVERAGEIFS(DONNEES!$O$2:$O$1501,DONNEES!$E$2:$E$1501,$A15),"") -> 22.289604

Sheet PAR_TOUR
A1: Résultats par tour de conversation
A2: Tour = position de la question dans sa conversation de 5 questions.
A4: Tour | B4: Notées | C4: Correct | D4: « Aucune info » à tort | E4: Valeur fausse | F4: Hors sujet | G4: % correct | H4: % aucune info | I4: % faux | J4: % hors sujet | K4: Latence moy. (s)
A5: 1 | B5: =COUNTIFS(DONNEES!$H$2:$H$1501,"NOTABLE",DONNEES!$L$2:$L$1501,"Correct",DONNEES!$C$2:$C$1501,$A5)+COUNTIFS(DONNEES!$H$2:$H$1501,"NOTABLE",DONNEES!$L$2:$L$1501,"Pas d’info à tort",DONNEES!$C$2:$C$1501,$A5)+COUNTIFS(DONNEES!$H$2:$H$1501,"NOTABLE",DONNEES!$L$2:$L$1501,"Incorrect",DONNEES!$C$2:$C$1501,$A5)+COUNTIFS(DONNEES!$H$2:$H$1501,"NOTABLE",DONNEES!$L$2:$L$1501,"Hors sujet",DONNEES!$C$2:$C$1501,$A5) -> 296 | C5: =COUNTIFS(DONNEES!$H$2:$H$1501,"NOTABLE",DONNEES!$L$2:$L$1501,"Correct",DONNEES!$C$2:$C$1501,$A5) -> 235 | D5: =COUNTIFS(DONNEES!$H$2:$H$1501,"NOTABLE",DONNEES!$L$2:$L$1501,"Pas d’info à tort",DONNEES!$C$2:$C$1501,$A5) -> 43 | E5: =COUNTIFS(DONNEES!$H$2:$H$1501,"NOTABLE",DONNEES!$L$2:$L$1501,"Incorrect",DONNEES!$C$2:$C$1501,$A5) -> 9 | F5: =COUNTIFS(DONNEES!$H$2:$H$1501,"NOTABLE",DONNEES!$L$2:$L$1501,"Hors sujet",DONNEES!$C$2:$C$1501,$A5) -> 9 | G5: =IF($B5=0,"",C5/$B5) -> 0.79391892 | H5: =IF($B5=0,"",D5/$B5) -> 0.14527027 | I5: =IF($B5=0,"",E5/$B5) -> 0.030405405 | J5: =IF($B5=0,"",F5/$B5) -> 0.030405405 | K5: =IFERROR(AVERAGEIFS(DONNEES!$O$2:$O$1501,DONNEES!$C$2:$C$1501,$A5),"") -> 38.271818
A6: 2 | B6: =COUNTIFS(DONNEES!$H$2:$H$1501,"NOTABLE",DONNEES!$L$2:$L$1501,"Correct",DONNEES!$C$2:$C$1501,$A6)+COUNTIFS(DONNEES!$H$2:$H$1501,"NOTABLE",DONNEES!$L$2:$L$1501,"Pas d’info à tort",DONNEES!$C$2:$C$1501,$A6)+COUNTIFS(DONNEES!$H$2:$H$1501,"NOTABLE",DONNEES!$L$2:$L$1501,"Incorrect",DONNEES!$C$2:$C$1501,$A6)+COUNTIFS(DONNEES!$H$2:$H$1501,"NOTABLE",DONNEES!$L$2:$L$1501,"Hors sujet",DONNEES!$C$2:$C$1501,$A6) -> 297 | C6: =COUNTIFS(DONNEES!$H$2:$H$1501,"NOTABLE",DONNEES!$L$2:$L$1501,"Correct",DONNEES!$C$2:$C$1501,$A6) -> 237 | D6: =COUNTIFS(DONNEES!$H$2:$H$1501,"NOTABLE",DONNEES!$L$2:$L$1501,"Pas d’info à tort",DONNEES!$C$2:$C$1501,$A6) -> 40 | E6: =COUNTIFS(DONNEES!$H$2:$H$1501,"NOTABLE",DONNEES!$L$2:$L$1501,"Incorrect",DONNEES!$C$2:$C$1501,$A6) -> 11 | F6: =COUNTIFS(DONNEES!$H$2:$H$1501,"NOTABLE",DONNEES!$L$2:$L$1501,"Hors sujet",DONNEES!$C$2:$C$1501,$A6) -> 9 | G6: =IF($B6=0,"",C6/$B6) -> 0.7979798 | H6: =IF($B6=0,"",D6/$B6) -> 0.13468013 | I6: =IF($B6=0,"",E6/$B6) -> 0.037037037 | J6: =IF($B6=0,"",F6/$B6) -> 0.03030303 | K6: =IFERROR(AVERAGEIFS(DONNEES!$O$2:$O$1501,DONNEES!$C$2:$C$1501,$A6),"") -> 12.815185
A7: 3 | B7: =COUNTIFS(DONNEES!$H$2:$H$1501,"NOTABLE",DONNEES!$L$2:$L$1501,"Correct",DONNEES!$C$2:$C$1501,$A7)+COUNTIFS(DONNEES!$H$2:$H$1501,"NOTABLE",DONNEES!$L$2:$L$1501,"Pas d’info à tort",DONNEES!$C$2:$C$1501,$A7)+COUNTIFS(DONNEES!$H$2:$H$1501,"NOTABLE",DONNEES!$L$2:$L$1501,"Incorrect",DONNEES!$C$2:$C$1501,$A7)+COUNTIFS(DONNEES!$H$2:$H$1501,"NOTABLE",DONNEES!$L$2:$L$1501,"Hors sujet",DONNEES!$C$2:$C$1501,$A7) -> 256 | C7: =COUNTIFS(DONNEES!$H$2:$H$1501,"NOTABLE",DONNEES!$L$2:$L$1501,"Correct",DONNEES!$C$2:$C$1501,$A7) -> 201 | D7: =COUNTIFS(DONNEES!$H$2:$H$1501,"NOTABLE",DONNEES!$L$2:$L$1501,"Pas d’info à tort",DONNEES!$C$2:$C$1501,$A7) -> 46 | E7: =COUNTIFS(DONNEES!$H$2:$H$1501,"NOTABLE",DONNEES!$L$2:$L$1501,"Incorrect",DONNEES!$C$2:$C$1501,$A7) -> 8 | F7: =COUNTIFS(DONNEES!$H$2:$H$1501,"NOTABLE",DONNEES!$L$2:$L$1501,"Hors sujet",DONNEES!$C$2:$C$1501,$A7) -> 1 | G7: =IF($B7=0,"",C7/$B7) -> 0.78515625 | H7: =IF($B7=0,"",D7/$B7) -> 0.1796875 | I7: =IF($B7=0,"",E7/$B7) -> 0.03125 | J7: =IF($B7=0,"",F7/$B7) -> 0.00390625 | K7: =IFERROR(AVERAGEIFS(DONNEES!$O$2:$O$1501,DONNEES!$C$2:$C$1501,$A7),"") -> 15.616061
A8: 4 | B8: =COUNTIFS(DONNEES!$H$2:$H$1501,"NOTABLE",DONNEES!$L$2:$L$1501,"Correct",DONNEES!$C$2:$C$1501,$A8)+COUNTIFS(DONNEES!$H$2:$H$1501,"NOTABLE",DONNEES!$L$2:$L$1501,"Pas d’info à tort",DONNEES!$C$2:$C$1501,$A8)+COUNTIFS(DONNEES!$H$2:$H$1501,"NOTABLE",DONNEES!$L$2:$L$1501,"Incorrect",DONNEES!$C$2:$C$1501,$A8)+COUNTIFS(DONNEES!$H$2:$H$1501,"NOTABLE",DONNEES!$L$2:$L$1501,"Hors sujet",DONNEES!$C$2:$C$1501,$A8) -> 219 | C8: =COUNTIFS(DONNEES!$H$2:$H$1501,"NOTABLE",DONNEES!$L$2:$L$1501,"Correct",DONNEES!$C$2:$C$1501,$A8) -> 186 | D8: =COUNTIFS(DONNEES!$H$2:$H$1501,"NOTABLE",DONNEES!$L$2:$L$1501,"Pas d’info à tort",DONNEES!$C$2:$C$1501,$A8) -> 25 | E8: =COUNTIFS(DONNEES!$H$2:$H$1501,"NOTABLE",DONNEES!$L$2:$L$1501,"Incorrect",DONNEES!$C$2:$C$1501,$A8) -> 6 | F8: =COUNTIFS(DONNEES!$H$2:$H$1501,"NOTABLE",DONNEES!$L$2:$L$1501,"Hors sujet",DONNEES!$C$2:$C$1501,$A8) -> 2 | G8: =IF($B8=0,"",C8/$B8) -> 0.84931507 | H8: =IF($B8=0,"",D8/$B8) -> 0.11415525 | I8: =IF($B8=0,"",E8/$B8) -> 0.02739726 | J8: =IF($B8=0,"",F8/$B8) -> 0.0091324201 | K8: =IFERROR(AVERAGEIFS(DONNEES!$O$2:$O$1501,DONNEES!$C$2:$C$1501,$A8),"") -> 12.335118
A9: 5 | B9: =COUNTIFS(DONNEES!$H$2:$H$1501,"NOTABLE",DONNEES!$L$2:$L$1501,"Correct",DONNEES!$C$2:$C$1501,$A9)+COUNTIFS(DONNEES!$H$2:$H$1501,"NOTABLE",DONNEES!$L$2:$L$1501,"Pas d’info à tort",DONNEES!$C$2:$C$1501,$A9)+COUNTIFS(DONNEES!$H$2:$H$1501,"NOTABLE",DONNEES!$L$2:$L$1501,"Incorrect",DONNEES!$C$2:$C$1501,$A9)+COUNTIFS(DONNEES!$H$2:$H$1501,"NOTABLE",DONNEES!$L$2:$L$1501,"Hors sujet",DONNEES!$C$2:$C$1501,$A9) -> 297 | C9: =COUNTIFS(DONNEES!$H$2:$H$1501,"NOTABLE",DONNEES!$L$2:$L$1501,"Correct",DONNEES!$C$2:$C$1501,$A9) -> 248 | D9: =COUNTIFS(DONNEES!$H$2:$H$1501,"NOTABLE",DONNEES!$L$2:$L$1501,"Pas d’info à tort",DONNEES!$C$2:$C$1501,$A9) -> 32 | E9: =COUNTIFS(DONNEES!$H$2:$H$1501,"NOTABLE",DONNEES!$L$2:$L$1501,"Incorrect",DONNEES!$C$2:$C$1501,$A9) -> 15 | F9: =COUNTIFS(DONNEES!$H$2:$H$1501,"NOTABLE",DONNEES!$L$2:$L$1501,"Hors sujet",DONNEES!$C$2:$C$1501,$A9) -> 2 | G9: =IF($B9=0,"",C9/$B9) -> 0.83501684 | H9: =IF($B9=0,"",D9/$B9) -> 0.10774411 | I9: =IF($B9=0,"",E9/$B9) -> 0.050505051 | J9: =IF($B9=0,"",F9/$B9) -> 0.0067340067 | K9: =IFERROR(AVERAGEIFS(DONNEES!$O$2:$O$1501,DONNEES!$C$2:$C$1501,$A9),"") -> 13.225455

Sheet PAR_CHAMP
A1: Résultats par champ
A2: Triés du plus faible au plus fort. Interpréter avec prudence sous 8 questions notées.
A4: Champ | B4: Notées | C4: Correct | D4: « Aucune info » à tort | E4: Valeur fausse | F4: Hors sujet | G4: % correct | H4: % aucune info | I4: % faux | J4: % hors sujet | K4: Latence moy. (s)
A5: Previous month SRI | B5: =COUNTIFS(DONNEES!$H$2:$H$1501,"NOTABLE",DONNEES!$L$2:$L$1501,"Correct",DONNEES!$G$2:$G$1501,$A5)+COUNTIFS(DONNEES!$H$2:$H$1501,"NOTABLE",DONNEES!$L$2:$L$1501,"Pas d’info à tort",DONNEES!$G$2:$G$1501,$A5)+COUNTIFS(DONNEES!$H$2:$H$1501,"NOTABLE",DONNEES!$L$2:$L$1501,"Incorrect",DONNEES!$G$2:$G$1501,$A5)+COUNTIFS(DONNEES!$H$2:$H$1501,"NOTABLE",DONNEES!$L$2:$L$1501,"Hors sujet",DONNEES!$G$2:$G$1501,$A5) -> 18 | C5: =COUNTIFS(DONNEES!$H$2:$H$1501,"NOTABLE",DONNEES!$L$2:$L$1501,"Correct",DONNEES!$G$2:$G$1501,$A5) -> 3 | D5: =COUNTIFS(DONNEES!$H$2:$H$1501,"NOTABLE",DONNEES!$L$2:$L$1501,"Pas d’info à tort",DONNEES!$G$2:$G$1501,$A5) -> 15 | E5: =COUNTIFS(DONNEES!$H$2:$H$1501,"NOTABLE",DONNEES!$L$2:$L$1501,"Incorrect",DONNEES!$G$2:$G$1501,$A5) -> 0 | F5: =COUNTIFS(DONNEES!$H$2:$H$1501,"NOTABLE",DONNEES!$L$2:$L$1501,"Hors sujet",DONNEES!$G$2:$G$1501,$A5) -> 0 | G5: =IF($B5=0,"",C5/$B5) -> 0.16666667 | H5: =IF($B5=0,"",D5/$B5) -> 0.83333333 | I5: =IF($B5=0,"",E5/$B5) -> 0 | J5: =IF($B5=0,"",F5/$B5) -> 0 | K5: =IFERROR(AVERAGEIFS(DONNEES!$O$2:$O$1501,DONNEES!$G$2:$G$1501,$A5),"") -> 26.377778
A6: Reference ESG Benchmark (EET 20370) | B6: =COUNTIFS(DONNEES!$H$2:$H$1501,"NOTABLE",DONNEES!$L$2:$L$1501,"Correct",DONNEES!$G$2:$G$1501,$A6)+COUNTIFS(DONNEES!$H$2:$H$1501,"NOTABLE",DONNEES!$L$2:$L$1501,"Pas d’info à tort",DONNEES!$G$2:$G$1501,$A6)+COUNTIFS(DONNEES!$H$2:$H$1501,"NOTABLE",DONNEES!$L$2:$L$1501,"Incorrect",DONNEES!$G$2:$G$1501,$A6)+COUNTIFS(DONNEES!$H$2:$H$1501,"NOTABLE",DONNEES!$L$2:$L$1501,"Hors sujet",DONNEES!$G$2:$G$1501,$A6) -> 14 | C6: =COUNTIFS(DONNEES!$H$2:$H$1501,"NOTABLE",DONNEES!$L$2:$L$1501,"Correct",DONNEES!$G$2:$G$1501,$A6) -> 3 | D6: =COUNTIFS(DONNEES!$H$2:$H$1501,"NOTABLE",DONNEES!$L$2:$L$1501,"Pas d’info à tort",DONNEES!$G$2:$G$1501,$A6) -> 7 | E6: =COUNTIFS(DONNEES!$H$2:$H$1501,"NOTABLE",DONNEES!$L$2:$L$1501,"Incorrect",DONNEES!$G$2:$G$1501,$A6) -> 4 | F6: =COUNTIFS(DONNEES!$H$2:$H$1501,"NOTABLE",DONNEES!$L$2:$L$1501,"Hors sujet",DONNEES!$G$2:$G$1501,$A6) -> 0 | G6: =IF($B6=0,"",C6/$B6) -> 0.21428571 | H6: =IF($B6=0,"",D6/$B6) -> 0.5 | I6: =IF($B6=0,"",E6/$B6) -> 0.28571429 | J6: =IF($B6=0,"",F6/$B6) -> 0 | K6: =IFERROR(AVERAGEIFS(DONNEES!$O$2:$O$1501,DONNEES!$G$2:$G$1501,$A6),"") -> 16.827857
A7: Volatility target | B7: =COUNTIFS(DONNEES!$H$2:$H$1501,"NOTABLE",DONNEES!$L$2:$L$1501,"Correct",DONNEES!$G$2:$G$1501,$A7)+COUNTIFS(DONNEES!$H$2:$H$1501,"NOTABLE",DONNEES!$L$2:$L$1501,"Pas d’info à tort",DONNEES!$G$2:$G$1501,$A7)+COUNTIFS(DONNEES!$H$2:$H$1501,"NOTABLE",DONNEES!$L$2:$L$1501,"Incorrect",DONNEES!$G$2:$G$1501,$A7)+COUNTIFS(DONNEES!$H$2:$H$1501,"NOTABLE",DONNEES!$L$2:$L$1501,"Hors sujet",DONNEES!$G$2:$G$1501,$A7) -> 14 | C7: =COUNTIFS(DONNEES!$H$2:$H$1501,"NOTABLE",DONNEES!$L$2:$L$1501,"Correct",DONNEES!$G$2:$G$1501,$A7) -> 3 | D7: =COUNTIFS(DONNEES!$H$2:$H$1501,"NOTABLE",DONNEES!$L$2:$L$1501,"Pas d’info à tort",DONNEES!$G$2:$G$1501,$A7) -> 10 | E7: =COUNTIFS(DONNEES!$H$2:$H$1501,"NOTABLE",DONNEES!$L$2:$L$1501,"Incorrect",DONNEES!$G$2:$G$1501,$A7) -> 0 | F7: =COUNTIFS(DONNEES!$H$2:$H$1501,"NOTABLE",DONNEES!$L$2:$L$1501,"Hors sujet",DONNEES!$G$2:$G$1501,$A7) -> 1 | G7: =IF($B7=0,"",C7/$B7) -> 0.21428571 | H7: =IF($B7=0,"",D7/$B7) -> 0.71428571 | I7: =IF($B7=0,"",E7/$B7) -> 0 | J7: =IF($B7=0,"",F7/$B7) -> 0.071428571 | K7: =IFERROR(AVERAGEIFS(DONNEES!$O$2:$O$1501,DONNEES!$G$2:$G$1501,$A7),"") -> 14.000714
A8: Implicit Transaction costs ex-post (EMT) | B8: =COUNTIFS(DONNEES!$H$2:$H$1501,"NOTABLE",DONNEES!$L$2:$L$1501,"Correct",DONNEES!$G$2:$G$1501,$A8)+COUNTIFS(DONNEES!$H$2:$H$1501,"NOTABLE",DONNEES!$L$2:$L$1501,"Pas d’info à tort",DONNEES!$G$2:$G$1501,$A8)+COUNTIFS(DONNEES!$H$2:$H$1501,"NOTABLE",DONNEES!$L$2:$L$1501,"Incorrect",DONNEES!$G$2:$G$1501,$A8)+COUNTIFS(DONNEES!$H$2:$H$1501,"NOTABLE",DONNEES!$L$2:$L$1501,"Hors sujet",DONNEES!$G$2:$G$1501,$A8) -> 15 | C8: =COUNTIFS(DONNEES!$H$2:$H$1501,"NOTABLE",DONNEES!$L$2:$L$1501,"Correct",DONNEES!$G$2:$G$1501,$A8) -> 4 | D8: =COUNTIFS(DONNEES!$H$2:$H$1501,"NOTABLE",DONNEES!$L$2:$L$1501,"Pas d’info à tort",DONNEES!$G$2:$G$1501,$A8) -> 2 | E8: =COUNTIFS(DONNEES!$H$2:$H$1501,"NOTABLE",DONNEES!$L$2:$L$1501,"Incorrect",DONNEES!$G$2:$G$1501,$A8) -> 9 | F8: =COUNTIFS(DONNEES!$H$2:$H$1501,"NOTABLE",DONNEES!$L$2:$L$1501,"Hors sujet",DONNEES!$G$2:$G$1501,$A8) -> 0 | G8: =IF($B8=0,"",C8/$B8) -> 0.26666667 | H8: =IF($B8=0,"",D8/$B8) -> 0.13333333 | I8: =IF($B8=0,"",E8/$B8) -> 0.6 | J8: =IF($B8=0,"",F8/$B8) -> 0 | K8: =IFERROR(AVERAGEIFS(DONNEES!$O$2:$O$1501,DONNEES!$G$2:$G$1501,$A8),"") -> 25.740625
A9: Official Risk Scale | B9: =COUNTIFS(DONNEES!$H$2:$H$1501,"NOTABLE",DONNEES!$L$2:$L$1501,"Correct",DONNEES!$G$2:$G$1501,$A9)+COUNTIFS(DONNEES!$H$2:$H$1501,"NOTABLE",DONNEES!$L$2:$L$1501,"Pas d’info à tort",DONNEES!$G$2:$G$1501,$A9)+COUNTIFS(DONNEES!$H$2:$H$1501,"NOTABLE",DONNEES!$L$2:$L$1501,"Incorrect",DONNEES!$G$2:$G$1501,$A9)+COUNTIFS(DONNEES!$H$2:$H$1501,"NOTABLE",DONNEES!$L$2:$L$1501,"Hors sujet",DONNEES!$G$2:$G$1501,$A9) -> 37 | C9: =COUNTIFS(DONNEES!$H$2:$H$1501,"NOTABLE",DONNEES!$L$2:$L$1501,"Correct",DONNEES!$G$2:$G$1501,$A9) -> 10 | D9: =COUNTIFS(DONNEES!$H$2:$H$1501,"NOTABLE",DONNEES!$L$2:$L$1501,"Pas d’info à tort",DONNEES!$G$2:$G$1501,$A9) -> 27 | E9: =COUNTIFS(DONNEES!$H$2:$H$1501,"NOTABLE",DONNEES!$L$2:$L$1501,"Incorrect",DONNEES!$G$2:$G$1501,$A9) -> 0 | F9: =COUNTIFS(DONNEES!$H$2:$H$1501,"NOTABLE",DONNEES!$L$2:$L$1501,"Hors sujet",DONNEES!$G$2:$G$1501,$A9) -> 0 | G9: =IF($B9=0,"",C9/$B9) -> 0.27027027 | H9: =IF($B9=0,"",D9/$B9) -> 0.72972973 | I9: =IF($B9=0,"",E9/$B9) -> 0 | J9: =IF($B9=0,"",F9/$B9) -> 0 | K9: =IFERROR(AVERAGEIFS(DONNEES!$O$2:$O$1501,DONNEES!$G$2:$G$1501,$A9),"") -> 21.380811
